<?xml version="1.0" ?>
<!-- =================================================================================== -->
<!-- |    This document was autogenerated by xacro from irb120.xacro                   | -->
<!-- |    EDITING THIS FILE BY HAND IS NOT RECOMMENDED                                 | -->
<!-- =================================================================================== -->
<robot name="abb_irb120_3_58" xmlns:xacro="http://ros.org/wiki/xacro">
    <!-- Conversion were obtained from http://www.e-paint.co.uk/Lab_values.asp
       unless otherwise stated. -->
    <!-- Actual colors -->
    <!-- NCS 2070-Y60R orange, standard robot color 1974 - May 2014 -->
    <!-- RAL 7035 light grey (abb graphite white), standard robot color May 2014 - current -->
    <!-- RAL 9003 signal white (abb white), cleanroom robot color -->
    <!-- RAL 7032 pebble gray, controller -->
    <!-- RAL 7012 basalt gray (abb dark gray) , robot primer -->
    <!-- RAL 7021 black gray (abb black) , robot with dark link color -->
    <!-- Other robot colours availble, but not limited too. -->
    <!-- RAL 3001 signal red -->
    <!-- RAL 3002 carmine red -->
    <!-- RAL 5002 ultramarine blue -->
    <!-- RAL 5015 sky blue -->
    <!-- RAL 6002 leaf green -->
    <!-- RAL 9002 gray white -->
    <!-- RAL 9010 pure white -->
    <!-- approximations -->
    <!-- yellow, collision model -->
    <!-- link list -->
    <!--<link name="Table_blue">
      <collision>
      <origin xyz="0 0 0" rpy="0 0 0"/>
      <geometry>
    <box size="0.05 0.05 0.05"/>
      </geometry>
    </collision>

    <visual>
      <origin xyz="0 0 0" rpy="0 0 0"/>
      <geometry>
    <box size="0.05 0.05 0.05 "/>
      </geometry>
      <material name="red"/>
    </visual>

    <inertial>
      <mass value="1" />
      <origin xyz="0 0 0" rpy="0 0 0"/>
      <inertia ixx="1" ixy="1" ixz="1" iyy="1" iyz="1" izz="1" />
    </inertial>
    </link> 

 <link name="Table_red">
      <collision>
      <origin xyz="0 0 0" rpy="0 0 0"/>
      <geometry>
    <box size="0.05 0.05 0.05"/>
      </geometry>
    </collision>

    <visual>
      <origin xyz="0 0 0" rpy="0 0 0"/>
      <geometry>
    <box size="0.05 0.05 0.05 "/>
      </geometry>
      <material name="red"/>
    </visual>

    <inertial>
      <mass value="1" />
      <origin xyz="0 0 0" rpy="0 0 0"/>
      <inertia ixx="1" ixy="1" ixz="1" iyy="1" iyz="1" izz="1" />
    </inertial>
    </link> 

 <link name="Table_green">
      <collision>
      <origin xyz="0 0 0" rpy="0 0 0"/>
      <geometry>
    <box size="0.05 0.05 0.05"/>
      </geometry>
    </collision>

    <visual>
      <origin xyz="0 0 0" rpy="0 0 0"/>
      <geometry>
    <box size="0.05 0.05 0.05 "/>
      </geometry>
      <material name="red"/>
    </visual>

    <inertial>
      <mass value="1" />
      <origin xyz="0 0 0" rpy="0 0 0"/>
      <inertia ixx="1" ixy="1" ixz="1" iyy="1" iyz="1" izz="1" />
    </inertial>
    </link> 

 <link name="Table_yellow">
      <collision>
      <origin xyz="0 0 0" rpy="0 0 0"/>
      <geometry>
    <box size="0.05 0.05 0.05"/>
      </geometry>
    </collision>

    <visual>
      <origin xyz="0 0 0" rpy="0 0 0"/>
      <geometry>
    <box size="0.05 0.05 0.05 "/>
      </geometry>
      <material name="red"/>
    </visual>

    <inertial>
      <mass value="1" />
      <origin xyz="0 0 0" rpy="0 0 0"/>
      <inertia ixx="1" ixy="1" ixz="1" iyy="1" iyz="1" izz="1" />
    </inertial>
    </link> -->

    <link name="base_link">
        <inertial>
            <mass value="6.215" />
            <origin rpy="0 0 0" xyz="-0.04204 8.01E-05 0.07964" />
            <inertia ixx="0.0247272" ixy="-8.0784E-05" ixz="0.00130902" iyy="0.0491285" iyz="-8.0419E-06" izz="0.0472376" />
        </inertial>

        <visual>
            <origin rpy="0 0 0" xyz="0 0 0" />
            <geometry>
                <mesh filename="package://abb_irb120_support/meshes/irb120_3_58/visual/base_link.stl" />
            </geometry>
            <material name="">
                <color rgba="0.7372549 0.3490196 0.1607843 1" />
            </material>
        </visual>
        <collision>
            <origin rpy="0 0 0" xyz="0 0 0" />
            <geometry>
                <mesh filename="package://abb_irb120_support/meshes/irb120_3_58/collision/base_link.stl" />
            </geometry>
            <material name="">
                <color rgba="1 1 0 1" />
            </material>
        </collision>
    </link>
    <link name="link_1">
        
        <inertial>
            <mass value="3.067" />
            <origin rpy="0 0 0" xyz="9.77E-05 -0.00012 0.23841" />
            <inertia ixx="0.0142175" ixy="-1.28579E-05" ixz="-2.31364E-05" iyy="0.0144041" iyz="1.93404E-05" izz="0.0104533" />
        </inertial>

        <visual>
            <origin rpy="0 0 0" xyz="0 0 0" />
            <geometry>
                <mesh filename="package://abb_irb120_support/meshes/irb120_3_58/visual/link_1.stl" />
            </geometry>
            <material name="">
                <color rgba="0.7372549 0.3490196 0.1607843 1" />
            </material>
        </visual>
        <collision>
            <origin rpy="0 0 0" xyz="0 0 0" />
            <geometry>
                <mesh filename="package://abb_irb120_support/meshes/irb120_3_58/collision/link_1.stl" />
            </geometry>
            <material name="">
                <color rgba="1 1 0 1" />
            </material>
        </collision>
    </link>
    <link name="link_2">
        
        <inertial>
            <mass value="3.909" />
            <origin rpy="0 0 0" xyz="0.00078 -0.00212 0.10124" />
            <inertia ixx="0.0603111" ixy="9.83431E-06" ixz="5.72407E-05" iyy="0.041569" iyz="-0.00050497" izz="0.0259548" />
        </inertial>

        <visual>
            <origin rpy="0 0 0" xyz="0 0 0" />
            <geometry>
                <mesh filename="package://abb_irb120_support/meshes/irb120_3_58/visual/link_2.stl" />
            </geometry>
            <material name="">
                <color rgba="0.7372549 0.3490196 0.1607843 1" />
            </material>
        </visual>
        <collision>
            <origin rpy="0 0 0" xyz="0 0 0" />
            <geometry>
                <mesh filename="package://abb_irb120_support/meshes/irb120_3_58/collision/link_2.stl" />
            </geometry>
            <material name="">
                <color rgba="1 1 0 1" />
            </material>
        </collision>
    </link>
    <link name="link_3">
        
        <inertial>
            <mass value="2.944" />
            <origin rpy="0 0 0" xyz="0.02281 0.00106 0.05791" />
            <inertia ixx="0.00835606" ixy="-8.01545E-05" ixz="0.00142884" iyy="0.016713" iyz="-0.000182227" izz="0.0126984" />
        </inertial>

        <visual>
            <origin rpy="0 0 0" xyz="0 0 0" />
            <geometry>
                <mesh filename="package://abb_irb120_support/meshes/irb120_3_58/visual/link_3.stl" />
            </geometry>
            <material name="">
                <color rgba="0.7372549 0.3490196 0.1607843 1" />
            </material>
        </visual>
        <collision>
            <origin rpy="0 0 0" xyz="0 0 0" />
            <geometry>
                <mesh filename="package://abb_irb120_support/meshes/irb120_3_58/collision/link_3.stl" />
            </geometry>
            <material name="">
                <color rgba="1 1 0 1" />
            </material>
        </collision>
    </link>
    <link name="link_4">
        
        <inertial>
            <mass value="1.328" />
            <origin rpy="0 0 0" xyz="0.2247 0.00015 0.00041" />
            <inertia ixx="0.00284661" ixy="-2.12765E-05" ixz="-1.6435E-05" iyy="0.00401346" iyz="1.31336E-05" izz="0.0052535" />
        </inertial>

        <visual>
            <origin rpy="0 0 0" xyz="0 0 0" />
            <geometry>
                <mesh filename="package://abb_irb120_support/meshes/irb120_3_58/visual/link_4.stl" />
            </geometry>
            <material name="">
                <color rgba="0.7372549 0.3490196 0.1607843 1" />
            </material>
        </visual>
        <collision>
            <origin rpy="0 0 0" xyz="0 0 0" />
            <geometry>
                <mesh filename="package://abb_irb120_support/meshes/irb120_3_58/collision/link_4.stl" />
            </geometry>
            <material name="">
                <color rgba="1 1 0 1" />
            </material>
        </collision>
    </link>
    <link name="link_5">
        
        <inertial>
            <mass value="0.546" />
            <origin rpy="0 0 0" xyz="-0.00109 3.68E-05 6.22E-05" />
            <inertia ixx="0.000404891" ixy="1.61943E-06" ixz="8.46805E-07" iyy="0.000892825" iyz="-1.51792E-08" izz="0.000815468" />
        </inertial>

        <visual>
            <origin rpy="0 0 0" xyz="0 0 0" />
            <geometry>
                <mesh filename="package://abb_irb120_support/meshes/irb120_3_58/visual/link_5.stl" />
            </geometry>
            <material name="">
                <color rgba="0.7372549 0.3490196 0.1607843 1" />
            </material>
        </visual>
        <collision>
            <origin rpy="0 0 0" xyz="0 0 0" />
            <geometry>
                <mesh filename="package://abb_irb120_support/meshes/irb120_3_58/collision/link_5.stl" />
            </geometry>
            <material name="">
                <color rgba="1 1 0 1" />
            </material>
        </collision>
    </link>
    <link name="link_6">
        
        <inertial>
            <mass value="0.137" />
            <origin rpy="0 0 0" xyz="-0.00706 -0.00017 -1.32E-06" />
            <inertia ixx="0.001" ixy="0" ixz="0" iyy="0.001" iyz="0" izz="0.001" />
        </inertial>

        <visual>
            <origin rpy="0 0 0" xyz="0 0 0" />
            <geometry>
                <mesh filename="package://abb_irb120_support/meshes/irb120_3_58/visual/link_6.stl" />
            </geometry>
            <material name="">
                <color rgba="0.1882353 0.1960784 0.2039216 1" />
            </material>
        </visual>
        <collision>
            <origin rpy="0 0 0" xyz="0 0 0" />
            <geometry>
                <mesh filename="package://abb_irb120_support/meshes/irb120_3_58/collision/link_6.stl" />
            </geometry>
            <material name="">
                <color rgba="1 1 0 1" />
            </material>
        </collision>
    </link>
    <link name="gripper_hand">
        <visual>
            <geometry>
                <mesh filename="package://franka_description/meshes/visual/hand.dae" />
            </geometry>
        </visual>
        <collision>
            <geometry>
                <mesh filename="package://franka_description/meshes/collision/hand.stl" />
            </geometry>
        </collision>
        
        <inertial>
            <mass value="0.1" />
            <inertia ixx="0.03" iyy="0.03" izz="0.03" ixy="0.0" ixz="0.0" iyz="0.0" />
        </inertial>

    </link>
    <link name="gripper_leftfinger">
        <visual>
            <geometry>
                <mesh filename="package://franka_description/meshes/visual/finger.dae" />
            </geometry>
        </visual>
        <collision>
            <geometry>
                <mesh filename="package://franka_description/meshes/collision/finger.stl" />
            </geometry>
        </collision>
        
        <inertial>
            <mass value="0.1" />
            <inertia ixx="0.03" iyy="0.03" izz="0.03" ixy="0.0" ixz="0.0" iyz="0.0" />
        </inertial>

    </link>
    <link name="gripper_rightfinger">
        <visual>
            <origin rpy="0 0 3.14159265359" xyz="0 0 0" />
            <geometry>
                <mesh filename="package://franka_description/meshes/visual/finger.dae" />
            </geometry>
        </visual>
        <collision>
            <origin rpy="0 0 3.14159265359" xyz="0 0 0" />
            <geometry>
                <mesh filename="package://franka_description/meshes/collision/finger.stl" />
            </geometry>
        </collision>
        
        <inertial>
            <mass value="0.1" />
            <inertia ixx="0.03" iyy="0.03" izz="0.03" ixy="0.0" ixz="0.0" iyz="0.0" />
        </inertial>

    </link>

    <!-- end of link list -->
    <!-- joint list -->
     <!--<joint name="base_link-Table1" type="fixed">
        <parent link="world"/>
        <child link="Table_blue"/>
        <origin rpy="0 0 0" xyz="0.5 0.2 0.05"/>
    </joint>

    <joint name="base_link-Table2" type="fixed">
        <parent link="world"/>
        <child link="Table_red"/>
        <origin rpy="0 0 0" xyz="0.5 -0.2 0.05"/>
    </joint>

    <joint name="base_link-Table3" type="fixed">
        <parent link="world"/>
        <child link="Table_green"/>
        <origin rpy="0 0 0" xyz="0.4 0.2 0.05"/>
    </joint>

    <joint name="base_link-Table4" type="fixed">
        <parent link="world"/>
        <child link="Table_yellow"/>
        <origin rpy="0 0 0" xyz="0.4 -0.2 0.05"/>
    </joint>-->

    <joint name="joint_1" type="revolute">
        <origin rpy="0 0 0" xyz="0 0 0" />
        <parent link="base_link" />
        <child link="link_1" />
        <limit effort="10" lower="-2.87979" upper="2.87979" velocity="4.36332" />
        <axis xyz="0 0 1" />
        <dynamics damping="0.0" friction="0.0" />
    </joint>
    <joint name="joint_2" type="revolute">
        <origin rpy="0 0 0" xyz="0 0 0.29" />
        <parent link="link_1" />
        <child link="link_2" />
        <limit effort="10" lower="-1.91986" upper="1.91986" velocity="4.36332" />
        <axis xyz="0 1 0" />
        <dynamics damping="0.0" friction="0.0" />
    </joint>
    <joint name="joint_3" type="revolute">
        <origin rpy="0 0 0" xyz="0 0 0.27" />
        <parent link="link_2" />
        <child link="link_3" />
        <limit effort="10" lower="-1.91986" upper="1.22173" velocity="4.36332" />
        <axis xyz="0 1 0" />
        <dynamics damping="0.7" friction="0.2" />
    </joint>
    <joint name="joint_4" type="revolute">
        <origin rpy="0 0 0" xyz="0 0 0.07" />
        <parent link="link_3" />
        <child link="link_4" />
        <limit effort="10" lower="-2.79253" upper="2.79253" velocity="5.58505" />
        <axis xyz="1 0 0" />
        <dynamics damping="0.0" friction="0.0" />
    </joint>
    <joint name="joint_5" type="revolute">
        <origin rpy="0 0 0" xyz="0.302 0 0" />
        <parent link="link_4" />
        <child link="link_5" />
        <limit effort="10" lower="-2.094395" upper="2.094395" velocity="5.58505" />
        <axis xyz="0 1 0" />
        <dynamics damping="0.0" friction="0.0" />
    </joint>
    <joint name="joint_6" type="revolute">
        <origin rpy="0 0 0" xyz="0.072 0 0" />
        <parent link="link_5" />
        <child link="link_6" />
        <limit effort="10" lower="-6.98132" upper="6.98132" velocity="7.33038" />
        <axis xyz="1 0 0" />
        <dynamics damping="0.0" friction="0.0" />
    </joint>
    <joint name="abb_hand_joint" type="fixed">
        <parent link="link_6" />
        <child link="gripper_hand" />
        <origin rpy="0 1.570796327 0" xyz="0 0 0" />
    </joint>
    <joint name="gripper_finger_joint1" type="prismatic">
        <parent link="gripper_hand" />
        <child link="gripper_leftfinger" />
        <origin rpy="0 0 0" xyz="0 0 0.0584" />
        <axis xyz="0 1 0" />
        <limit effort="20" lower="0.0" upper="0.04" velocity="0.2" />
    </joint>
    <joint name="gripper_finger_joint2" type="prismatic">
        <parent link="gripper_hand" />
        <child link="gripper_rightfinger" />
        <origin rpy="0 0 0" xyz="0 0 0.0584" />
        <axis xyz="0 -1 0" />
        <limit effort="20" lower="0.0" upper="0.04" velocity="0.2" />
        <!-- <mimic joint="gripper_finger_joint1" /> -->
    </joint>
    <!-- end of joint list -->
    <!-- ROS base_link to ABB World Coordinates transform -->
    <link name="world"/>
    <joint name="base_link_base" type="fixed">
        <parent link="world" />
        <child link="base_link" />
    </joint>
    
    <transmission name="trans_joint_1">
        <type>transmission_interface/SimpleTransmission</type>
        <joint name="joint_1">
            <hardwareInterface>hardware_interface/EffortJointInterface</hardwareInterface>
        </joint>
        <actuator name="joint_1_motor">
            <hardwareInterface>hardware_interface/EffortJointInterface</hardwareInterface>
            <mechanicalReduction>1</mechanicalReduction>
        </actuator>
    </transmission>
    <transmission name="trans_joint_2">
        <type>transmission_interface/SimpleTransmission</type>
        <joint name="joint_2">
            <hardwareInterface>hardware_interface/EffortJointInterface</hardwareInterface>
        </joint>
        <actuator name="joint_2_motor">
            <hardwareInterface>hardware_interface/EffortJointInterface</hardwareInterface>
            <mechanicalReduction>1</mechanicalReduction>
        </actuator>
    </transmission>
    <transmission name="trans_joint_3">
        <type>transmission_interface/SimpleTransmission</type>
        <joint name="joint_3">
            <hardwareInterface>hardware_interface/EffortJointInterface</hardwareInterface>
        </joint>
        <actuator name="joint_3_motor">
            <hardwareInterface>hardware_interface/EffortJointInterface</hardwareInterface>
            <mechanicalReduction>1</mechanicalReduction>
        </actuator>
    </transmission>
    <transmission name="trans_joint_4">
        <type>transmission_interface/SimpleTransmission</type>
        <joint name="joint_4">
            <hardwareInterface>hardware_interface/EffortJointInterface</hardwareInterface>
        </joint>
        <actuator name="joint_4_motor">
            <hardwareInterface>hardware_interface/EffortJointInterface</hardwareInterface>
            <mechanicalReduction>1</mechanicalReduction>
        </actuator>
    </transmission>
    <transmission name="trans_joint_5">
        <type>transmission_interface/SimpleTransmission</type>
        <joint name="joint_5">
            <hardwareInterface>hardware_interface/EffortJointInterface</hardwareInterface>
        </joint>
        <actuator name="joint_5_motor">
            <hardwareInterface>hardware_interface/EffortJointInterface</hardwareInterface>
            <mechanicalReduction>1</mechanicalReduction>
        </actuator>
    </transmission>
    <transmission name="trans_joint_6">
        <type>transmission_interface/SimpleTransmission</type>
        <joint name="joint_6">
            <hardwareInterface>hardware_interface/EffortJointInterface</hardwareInterface>
        </joint>
        <actuator name="joint_6_motor">
            <hardwareInterface>hardware_interface/EffortJointInterface</hardwareInterface>
            <mechanicalReduction>1</mechanicalReduction>
        </actuator>
    </transmission>
    <transmission name="trans_gripper_finger_joint1">
        <type>transmission_interface/SimpleTransmission</type>
        <joint name="gripper_finger_joint1">
            <hardwareInterface>hardware_interface/EffortJointInterface</hardwareInterface>
        </joint>
        <actuator name="gripper_finger_joint1_motor">
            <hardwareInterface>hardware_interface/EffortJointInterface</hardwareInterface>
            <mechanicalReduction>1</mechanicalReduction>
        </actuator>
    </transmission>
    <transmission name="trans_gripper_finger_joint2">
        <type>transmission_interface/SimpleTransmission</type>
        <joint name="gripper_finger_joint2">
            <hardwareInterface>hardware_interface/EffortJointInterface</hardwareInterface>
        </joint>
        <actuator name="gripper_finger_joint2_motor">
            <hardwareInterface>hardware_interface/EffortJointInterface</hardwareInterface>
            <mechanicalReduction>1</mechanicalReduction>
        </actuator>
    </transmission>
    <!-- Gazebo-specific link properties -->
    <gazebo reference="base_link">
        <material>Gazebo/Orange</material>
        <turnGravityOff>false</turnGravityOff>
    </gazebo>
    <gazebo reference="link_1">
        <material>Gazebo/Orange</material>
        <turnGravityOff>true</turnGravityOff>
    </gazebo>
    <gazebo reference="link_2">
        <material>Gazebo/Orange</material>
        <turnGravityOff>true</turnGravityOff>
    </gazebo>  
    <gazebo reference="link_3">
        <material>Gazebo/Orange</material>
        <turnGravityOff>true</turnGravityOff>
    </gazebo>
    <gazebo reference="link_4">
        <material>Gazebo/Orange</material>
        <turnGravityOff>true</turnGravityOff>
    </gazebo>
    <gazebo reference="link_5">
        <material>Gazebo/Orange</material>
        <turnGravityOff>true</turnGravityOff>
    </gazebo>
    <gazebo reference="link_6">
        <material>Gazebo/Black</material>
        <turnGravityOff>true</turnGravityOff>
    </gazebo>
    <gazebo reference="gripper_hand">
        <material>Gazebo/Black</material>
        <turnGravityOff>true</turnGravityOff>
    </gazebo>
    <gazebo reference="gripper_rightfinger">
        <material>Gazebo/Black</material>
        <turnGravityOff>true</turnGravityOff>
    </gazebo>    
    <gazebo reference="gripper_leftfinger">
        <material>Gazebo/Black</material>
        <turnGravityOff>true</turnGravityOff>
    </gazebo>
     <!--<gazebo reference="Table_blue">
       <material>Gazebo/Blue</material>
       <turnGravityOff>false</turnGravityOff>
    </gazebo> 

      <gazebo reference="Table_red">
       <material>Gazebo/Red</material>
       <turnGravityOff>false</turnGravityOff>
    </gazebo> 

     <gazebo reference="Table_green">
       <material>Gazebo/Green</material>
       <turnGravityOff>false</turnGravityOff>
    </gazebo> 

     <gazebo reference="Table_yellow">
       <material>Gazebo/Yellow</material>
       <turnGravityOff>false</turnGravityOff>
    </gazebo>-->
    
    <!-- ros_control plugin -->
    <gazebo>
        <plugin name="gazebo_ros_control" filename="libgazebo_ros_control.so">
            <robotNamespace>/</robotNamespace>
            <robotSimType>gazebo_ros_control/DefaultRobotHWSim</robotSimType>
            <legacyModeNS>true</legacyModeNS>
        </plugin>
    </gazebo>


 <!-- Camera -->
  <link name="camera_link">
    <collision>
      <origin xyz="0 0 0" rpy="0 0 0"/>
      <geometry>
    <box size="0.05 0.1 0.05"/>
      </geometry>
    </collision>

    <visual>
      <origin xyz="0 0 0" rpy="0 0 0"/>
      <geometry>
    <box size="0.05 0.1 0.05 "/>
      </geometry>
      <material name="red"/>
    </visual>

    <inertial>
      <mass value="1e-5" />
      <origin xyz="0 0 0" rpy="0 0 0"/>
      <inertia ixx="1e-6" ixy="0" ixz="0" iyy="1e-6" iyz="0" izz="1e-6" />
    </inertial>
  </link>

    <joint name="camera_joint" type="fixed">
    <axis xyz="0 1 0" />
    <origin xyz="0.4 0 3.024" rpy="0 1.57 1.57"/> 
    <parent link="world"/>
    <child link="camera_link"/>
  </joint>

<!-- camera -->
  <gazebo reference="camera_link">
    <sensor type="depth" name="camera1">
      <update_rate>30.0</update_rate>
      <camera name="head">
        <horizontal_fov>1.3962634</horizontal_fov>
        <image>
          <width>800</width>
          <height>800</height>
          <format>R8G8B8</format>
        </image>
        <clip>
          <near>0.02</near>
          <far>300</far>
        </clip>
        <noise>
          <type>gaussian</type>
          <!-- Noise is sampled independently per pixel on each frame.
               That pixel's noise value is added to each of its color
               channels, which at that point lie in the range [0,1]. -->
          <mean>0.0</mean>
          <stddev>0.007</stddev>
        </noise>
      </camera>
      <plugin name="camera_controller" filename="libgazebo_ros_openni_kinect.so">
        <alwaysOn>true</alwaysOn>
        <updateRate>0.0</updateRate>
        <cameraName>abb_irb120_3_58/camera1</cameraName>
        <pointCloudTopicName>point_cloud</pointCloudTopicName>
        <imageTopicName>image_raw</imageTopicName>
        <cameraInfoTopicName>camera_info</cameraInfoTopicName>
        <depthImageTopicName>depth_raw</depthImageTopicName>
        <frameName>camera_link</frameName>
        <hackBaseline>0.07</hackBaseline>
        <distortionK1>0.0</distortionK1>
        <distortionK2>0.0</distortionK2>
        <distortionK3>0.0</distortionK3>
        <distortionT1>0.0</distortionT1>
        <distortionT2>0.0</distortionT2>
      </plugin>
    </sensor>
  </gazebo>

</robot>
